Workbook

Sheet февраль
A1: ДОНЕСЕНИЕ №
A2: о наличии и движении ГСМ и ТС 1 гр. ЦМТО войсковой части 2187 по состоянию на | J2: 46073
A3: № п/п | B3: Наименование материальных средств | F3: Единица измерения | G3: Категория | H3: Остаток на начало отчетного периода | I3: Прибыло | M3: Убыло | Q3: Остаток на конец отчетного периода | R3: Положено израсходовать по норме | S3: Экономия | T3: Перерасход
I4: со склада воинской части | J4: из других воинских частей (подразделений) | K4: прочий приход | L4: Всего | M4: фактически сожжено в двигателях, израсходовано на эксплуатационные нужды | N4: передано другим воинским частям (подразделениям) | O4: прочий расход | P4: всего
A5: 1 | B5: 2 | F5: 3 | G5: 4 | H5: 5 | I5: 6 | J5: 7 | K5: 8 | L5: 9 | M5: 10 | N5: 11 | O5: 12 | P5: 13 | Q5: 14 | R5: 15 | S5: 16 | T5: 17
A6: 1 | B6: Автомобильный бензин АИ-92-К5 | F6: л | G6: - | H6: 3646 | I6: =$G41 -> 3552 | J6: =$G48 -> 71 | K6: =$G51 -> 0 | L6: =SUM(I6:K6) -> 3623 | M6: =$G53 -> 3369 | N6: =$G56 -> 147 | O6: =$G59 -> 2364 | P6: =SUM(M6:O6) -> 5880 | Q6: =H6+L6-P6 -> 1389 | R6: =M6+S6 -> 3369 | S6: 0 | T6: 0
B7: сентябрь | G7: - | H7: =январь!Q7 -> -172 | L7: =SUM(I7:K7) -> 0 | M7: =R7-S7 -> 0 | N7: 14 | O7: 158 | P7: =SUM(M7:O7) -> 172 | Q7: =H7+L7-P7 -> -344 | R7: =M7+S7 -> 0 | S7: 0 | T7: 0
B8: октябрь | G8: - | H8: =январь!Q8 -> 0 | L8: =SUM(I8:K8) -> 0 | M8: =R8-S8 -> 0 | P8: =SUM(M8:O8) -> 0 | Q8: =H8+L8-P8 -> 2966 | R8: =M8+S8 -> 0 | S8: 0 | T8: 0
B9: ноябрь | G9: - | H9: =январь!Q9 -> 0 | L9: =SUM(I9:K9) -> 0 | M9: =R9-S9 -> 0 | P9: =SUM(M9:O9) -> 0 | Q9: =H9+L9-P9 -> 0 | R9: =M9+S9 -> 0 | S9: 0 | T9: 0
B10: декабрь | G10: - | H10: =январь!Q10 -> 0 | L10: =SUM(I10:K10) -> 0 | M10: =R10-S10 -> 0 | P10: =SUM(M10:O10) -> 0 | Q10: =H10+L10-P10 -> 0 | R10: =M10+S10 -> 0 | S10: 0 | T10: 0
B11: январь | G11: - | H11: =январь!Q11 -> 4034 | I11: 3763 | J11: 271 | L11: =SUM(I11:K11) -> 4034 | M11: =R11-S11 -> 4235 | P11: =SUM(M11:O11) -> 0 | Q11: =H11+L11-P11 -> 8068 | R11: =M11+S11 -> 4235 | S11: 0 | T11: 0
G12: - | H12: =январь!Q12 -> 0 | L12: =SUM(I12:K12) -> 0 | M12: =R12-S12 -> 0 | P12: =SUM(M12:O12) -> 0 | Q12: =H12+L12-P12 -> 2966 | R12: =M12+S12 -> 0 | S12: 0 | T12: 0
G13: - | H13: =январь!Q13 -> 0 | L13: =SUM(I13:K13) -> 0 | M13: =R13-S13 -> 0 | P13: =SUM(M13:O13) -> 0 | Q13: =H13+L13-P13 -> 0 | R13: =M13+S13 -> 0 | S13: 0 | T13: 0
G14: - | H14: =январь!Q14 -> 0 | L14: =SUM(I14:K14) -> 0 | M14: =R14-S14 -> 0 | P14: =SUM(M14:O14) -> 0 | Q14: =H14+L14-P14 -> 0 | R14: =M14+S14 -> 0 | S14: 0 | T14: 0
A15: 2 | B15: Дизельное топливо ДТ-Л-К5 | F15: л | G15: - | H15: =январь!Q15 -> 0 | I15: 0 | J15: 0 | K15: 0 | L15: =SUM(I15:K15) -> 0 | M15: 0 | N15: 0 | O15: 0 | P15: =SUM(M15:O15) -> 0 | Q15: =H15+L15-P15 -> 0 | R15: =M15+S15 -> 0 | S15: 0 | T15: 0
A16: 3 | B16: Дизельное топливо ДТ-З-К5 | F16: л | G16: - | H16: =январь!Q16 -> 2452 | I16: =$H41 -> 3071 | J16: =$H48 -> 160 | K16: =$H51 -> 0 | L16: =SUM(I16:K16) -> 3231 | M16: =$H53 -> 3537 | N16: =$H56 -> 0 | O16: =$H59 -> 0 | P16: =SUM(M16:O16) -> 3537 | Q16: =H16+L16-P16 -> 2146 | R16: =M16+S16 -> 3537 | S16: 0 | T16: 0
A17: 4 | B17: Автомобильный бензин АИ-95-К5 | F17: л | G17: - | H17: =январь!Q17 -> 159 | I17: =$I41 -> 715 | J17: =$I48 -> 0 | K17: =$I51 -> 0 | L17: =SUM(I17:K17) -> 715 | M17: =$I53 -> 744 | N17: =$I56 -> 0 | O17: =$I59 -> 0 | P17: =SUM(M17:O17) -> 744 | Q17: =H17+L17-P17 -> 130 | R17: =M17+S17 -> 744 | S17: 0 | T17: 0
A18: 5 | B18: Масло моторное М-8В | F18: л | G18: - | H18: 0 | I18: =$J41 -> 6.5 | J18: =$J48 -> 0 | K18: =$J51 -> 0 | L18: =SUM(I18:K18) -> 6.5 | M18: =$J53 -> 6.5 | N18: =$J56 -> 0 | O18: =$J59 -> 0 | P18: =SUM(M18:O18) -> 6.5 | Q18: =H18+L18-P18 -> 0 | R18: =M18+S18 -> 6.5 | S18: 0 | T18: 0
A19: 6 | B19: Масло моторное 5W-30 SN/CF | F19: л | G19: - | H19: =январь!Q19 -> 0 | I19: =$L41 -> 0 | J19: =$L48 -> 0 | K19: =$L51 -> 0 | L19: =SUM(I19:K19) -> 0 | M19: =$L53 -> 0 | N19: =$L56 -> 0 | O19: =$L59 -> 0 | P19: =SUM(M19:O19) -> 0 | Q19: =H19+L19-P19 -> 0 | R19: =M19+S19 -> 0 | S19: 0 | T19: 0
A20: 7 | B20: Масло трансмис. ТЭП-15 | F20: л | G20: - | H20: =январь!Q20 -> 0 | I20: =$Q41 -> 0 | J20: =$Q48 -> 0 | K20: =$Q51 -> 0 | L20: =SUM(I20:K20) -> 0 | M20: =$Q53 -> 0 | N20: =$Q56 -> 0 | O20: =$Q59 -> 0 | P20: =SUM(M20:O20) -> 0 | Q20: =H20+L20-P20 -> 0 | R20: =M20+S20 -> 0 | S20: 0 | T20: 0
A21: 8 | B21: Масло марки «Р» | F21: л | G21: - | H21: =январь!Q21 -> 0 | I21: =$S41 -> 0 | J21: =$S48 -> 0 | K21: =$S51 -> 0 | L21: =SUM(I21:K21) -> 0 | M21: =$S53 -> 0 | N21: =$S56 -> 0 | O21: =$S59 -> 0 | P21: =SUM(M21:O21) -> 0 | Q21: =H21+L21-P21 -> 0 | R21: =M21+S21 -> 0 | S21: 0 | T21: 0
A22: 9 | B22: Масло моторное 5W-40 SN/CF (синт.) | F22: л | G22: - | H22: =январь!Q22 -> 0 | I22: =$N41 -> 0 | J22: =$N48 -> 0 | K22: =$N51 -> 0 | L22: =SUM(I22:K22) -> 0 | M22: =$N53 -> 0 | N22: =$N56 -> 0 | O22: =$N59 -> 0 | P22: =SUM(M22:O22) -> 0 | Q22: =H22+L22-P22 -> 0 | R22: =M22+S22+O22 -> 0 | S22: 0 | T22: 0
A23: 10 | B23: Масло моторное 5W-40 SL/CF (полусинт.) | F23: л | G23: - | H23: =январь!Q23 -> 0 | I23: =$M41 -> 1 | J23: =$M48 -> 0 | K23: =$M51 -> 0 | L23: =SUM(I23:K23) -> 1 | M23: =$M53 -> 1 | N23: =$M56 -> 0 | O23: =$M59 -> 0 | P23: =SUM(M23:O23) -> 1 | Q23: =H23+L23-P23 -> 0 | R23: =M23+S23+O23 -> 1 | S23: 0 | T23: 0
A24: 11 | B24: Масло моторное 10W-40 SL/CF | F24: л | G24: - | H24: =январь!Q24 -> 0 | I24: =$O41 -> 8 | J24: =$O48 -> 0 | K24: =$O51 -> 0 | L24: =SUM(I24:K24) -> 8 | M24: =$O53 -> 8 | N24: =$O56 -> 0 | O24: =$O59 -> 0 | P24: =SUM(M24:O24) -> 8 | Q24: =H24+L24-P24 -> 0 | R24: =M24+S24+O24 -> 8 | S24: 0 | T24: 0
A25: 12 | B25: Масло моторное 10W-40 СI-4/CL | F25: л | G25: - | H25: =январь!Q25 -> 0 | I25: =$P41 -> 0 | J25: =$P48 -> 0 | K25: =$P51 -> 0 | L25: =SUM(I25:K25) -> 0 | M25: =$P53 -> 0 | N25: =$P56 -> 0 | O25: =$P59 -> 0 | P25: =SUM(M25:O25) -> 0 | Q25: =H25+L25-P25 -> 0 | R25: =M25+S25 -> 0 | S25: 0 | T25: 0
A26: 13 | B26: Масло трансм. 75W-90 API GL-5 | F26: л | G26: - | H26: =январь!Q26 -> 0 | I26: =$R41 -> 0 | J26: =$R48 -> 0 | K26: =$R51 -> 0 | L26: =SUM(I26:K26) -> 0 | M26: =$R53 -> 0 | N26: =$R56 -> 0 | O26: =$R59 -> 0 | P26: =SUM(M26:O26) -> 0 | Q26: =H26+L26-P26 -> 0 | R26: =M26+S26 -> 0 | S26: 0 | T26: 0
A27: 14 | B27: Т/Ж «Dot-4» | F27: л | G27: - | H27: =январь!Q27 -> 0 | I27: 0 | J27: 0 | K27: 0 | L27: =SUM(I27:K27) -> 0 | M27: 0 | N27: 0 | O27: 0 | P27: =SUM(M27:O27) -> 0 | Q27: =H27+L27-P27 -> 0 | R27: =M27+S27 -> 0 | S27: 0 | T27: 0
A28: 15 | B28: Тосол-А40 | F28: л | G28: - | H28: =январь!Q28 -> 467.3 | I28: 0 | J28: 0 | K28: 0 | L28: =SUM(I28:K28) -> 0 | M28: 8.2 | N28: 0 | O28: 0 | P28: =SUM(M28:O28) -> 8.2 | Q28: =H28+L28-P28 -> 459.1 | R28: =M28+S28 -> 8.2 | S28: 0 | T28: 0
A29: 16 | B29: Антифриз зелен. | F29: л | G29: - | H29: =январь!Q29 -> 124.7 | I29: 0 | J29: 0 | K29: 0 | L29: =SUM(I29:K29) -> 0 | M29: 2.3 | N29: 0 | O29: 0 | P29: =SUM(M29:O29) -> 2.3 | Q29: =H29+L29-P29 -> 122.4 | R29: =M29+S29 -> 2.3 | S29: 0 | T29: 0
A30: 17 | B30: Антифриз красн. | F30: л | G30: - | H30: =январь!Q30 -> 59.5 | I30: 0 | J30: 0 | K30: 0 | L30: =SUM(I30:K30) -> 0 | M30: 1.5 | N30: 0 | O30: 0 | P30: =SUM(M30:O30) -> 1.5 | Q30: =H30+L30-P30 -> 58 | R30: =M30+S30 -> 1.5 | S30: 0 | T30: 0
A31: 18 | B31: Реагент AdBlue | F31: л | G31: - | H31: =январь!Q31 -> 10.9 | I31: 0 | J31: 0 | K31: 0 | L31: =SUM(I31:K31) -> 0 | M31: 3.8 | N31: 0 | O31: 0 | P31: =SUM(M31:O31) -> 3.8 | Q31: =H31+L31-P31 -> 7.1 | R31: =M31+S31 -> 3.8 | S31: 0 | T31: 0
A32: 19 | B32: Топливная карта | F32: шт. | G32: - | H32: =январь!Q32 -> 1 | I32: 0 | J32: 0 | K32: 0 | L32: =SUM(I32:K32) -> 0 | M32: 0 | N32: 0 | O32: 0 | P32: =SUM(M32:O32) -> 0 | Q32: 1 | R32: =M32+S32 -> 0 | S32: 0 | T32: 0
A33: Итого наименований:20 (двадцать)
A34: Наименование графы | B34: Откуда прибыло, куда убыло | D34: Наименование документа | E34: №, дата документа | G34: Наименование и количество ГСМ, ТС
G35: АИ-92 | H35: ДТ-З | I35: АИ-95 | J35: М-8В | K35: М-10Г2/М-10Г2к | L35: 5W-30 SN/CF | M35: 5W-40 SL/CF | N35: 5W-40 SN/CF син. | O35: 10W-40 SL/CF | P35: 10W-40 CI-4/CL | Q35: ТЭП-15 | R35: 75W-90 GL-5 | S35: Масло марки «Р» | T35: AdBlue
A36: 6 | B36: Склад в/ч | D36: Р/в | E36: № 557, 557/1/2/3/4/5 | G36: 3552 | H36: 3071 | I36: 715 | J36: 6.5 | K36: 0 | L36: 0 | M36: 1 | N36: 0 | O36: 8 | P36: 0 | Q36: 0 | R36: 0 | S36: 0 | T36: 0
B37: Склад в/ч | D37: Накладная | G37: 0 | H37: 0 | I37: 0 | J37: 0 | K37: 0 | L37: 0 | M37: 0 | N37: 0 | O37: 0 | P37: 0 | Q37: 0 | R37: 0 | S37: 0 | T37: 0
D38: Накладная | G38: 0 | H38: 0 | I38: 0 | J38: 0 | K38: 0 | L38: 0 | M38: 0 | N38: 0 | O38: 0 | P38: 0 | Q38: 0 | R38: 0 | S38: 0 | T38: 0
D39: Накладная | G39: 0 | H39: 0 | I39: 0 | J39: 0 | K39: 0 | L39: 0 | M39: 0 | N39: 0 | O39: 0 | P39: 0 | Q39: 0 | R39: 0 | S39: 0 | T39: 0
B40: Склад в/ч | D40: Накладная | G40: 0 | H40: 0 | I40: 0 | J40: 0 | K40: 0 | L40: 0 | M40: 0 | N40: 0 | O40: 0 | P40: 0 | Q40: 0 | R40: 0 | S40: 0 | T40: 0
...

Sheet январь
A1: ДОНЕСЕНИЕ №
A2: о наличии и движении ГСМ и ТС 1 гр. ЦМТО войсковой части 2187 по состоянию на | J2: 46042
A3: № п/п | B3: Наименование материальных средств | F3: Единица измерения | G3: Категория | H3: Остаток на начало отчетного периода | I3: Прибыло | M3: Убыло | Q3: Остаток на конец отчетного периода | R3: Положено израсходовать по норме | S3: Экономия | T3: Перерасход
I4: со склада воинской части | J4: из других воинских частей (подразделений) | K4: прочий приход | L4: Всего | M4: фактически сожжено в двигателях, израсходовано на эксплуатационные нужды | N4: передано другим воинским частям (подразделениям) | O4: прочий расход | P4: всего
A5: 1 | B5: 2 | F5: 3 | G5: 4 | H5: 5 | I5: 6 | J5: 7 | K5: 8 | L5: 9 | M5: 10 | N5: 11 | O5: 12 | P5: 13 | Q5: 14 | R5: 15 | S5: 16 | T5: 17
A6: 1 | B6: Автомобильный бензин АИ-92-К5 | F6: л | G6: - | H6: 3161 | I6: =$G41 -> 4160 | J6: =$G48 -> 271 | K6: =$G51 -> 0 | L6: =SUM(I6:K6) -> 4431 | M6: =$G53 -> 4325 | N6: =$G56 -> 301 | O6: =$G59 -> 0 | P6: =SUM(M6:O6) -> 4626 | Q6: =H6+L6-P6 -> 2966 | R6: =M6+S6 -> 4325 | S6: 0 | T6: 0
B7: сентябрь | G7: - | L7: =SUM(I7:K7) -> 0 | M7: =R7-S7 -> 0 | N7: 14 | O7: 158 | P7: =SUM(M7:O7) -> 172 | Q7: =H7+L7-P7 -> -172 | R7: =M7+S7 -> 0 | S7: 0 | T7: 0
B8: октябрь | G8: - | L8: =SUM(I8:K8) -> 0 | M8: =R8-S8 -> 0 | P8: =SUM(M8:O8) -> 0 | Q8: =H8+L8-P8 -> 0 | R8: =M8+S8 -> 0 | S8: 0 | T8: 0
B9: ноябрь | G9: - | L9: =SUM(I9:K9) -> 0 | M9: =R9-S9 -> 0 | P9: =SUM(M9:O9) -> 0 | Q9: =H9+L9-P9 -> 0 | R9: =M9+S9 -> 0 | S9: 0 | T9: 0
B10: декабрь | G10: - | L10: =SUM(I10:K10) -> 0 | M10: =R10-S10 -> 0 | P10: =SUM(M10:O10) -> 0 | Q10: =H10+L10-P10 -> 0 | R10: =M10+S10 -> 0 | S10: 0 | T10: 0
B11: январь | G11: - | I11: 3763 | J11: 271 | L11: =SUM(I11:K11) -> 4034 | M11: =R11-S11 -> 0 | P11: =SUM(M11:O11) -> 0 | Q11: =H11+L11-P11 -> 4034 | R11: =M11+S11 -> 0 | S11: 0 | T11: 0
G12: - | L12: =SUM(I12:K12) -> 0 | M12: =R12-S12 -> 4235 | P12: =SUM(M12:O12) -> 0 | Q12: =H12+L12-P12 -> 0 | R12: =M12+S12 -> 4235 | S12: 0 | T12: 0
G13: - | L13: =SUM(I13:K13) -> 0 | M13: =R13-S13 -> 0 | P13: =SUM(M13:O13) -> 0 | Q13: =H13+L13-P13 -> 0 | R13: =M13+S13 -> 0 | S13: 0 | T13: 0
G14: - | L14: =SUM(I14:K14) -> 0 | M14: =R14-S14 -> 0 | P14: =SUM(M14:O14) -> 0 | Q14: =H14+L14-P14 -> 0 | R14: =M14+S14 -> 0 | S14: 0 | T14: 0
A15: 2 | B15: Дизельное топливо ДТ-Л-К5 | F15: л | G15: - | H15: 0 | I15: 0 | J15: 0 | K15: 0 | L15: =SUM(I15:K15) -> 0 | M15: 0 | N15: 0 | O15: 0 | P15: =SUM(M15:O15) -> 0 | Q15: =H15+L15-P15 -> 0 | R15: =M15+S15 -> 0 | S15: 0 | T15: 0
A16: 3 | B16: Дизельное топливо ДТ-З-К5 | F16: л | G16: - | H16: 1555 | I16: =$H41 -> 4001 | J16: =$H48 -> 0 | K16: =$H51 -> 235 | L16: =SUM(I16:K16) -> 4236 | M16: =$H53 -> 3339 | N16: =$H56 -> 0 | O16: =$H59 -> 0 | P16: =SUM(M16:O16) -> 3339 | Q16: =H16+L16-P16 -> 2452 | R16: =M16+S16 -> 3339 | S16: 0 | T16: 0
A17: 4 | B17: Автомобильный бензин АИ-95-К5 | F17: л | G17: - | H17: 141 | I17: =$I41 -> 399 | J17: =$I48 -> 0 | K17: =$I51 -> 0 | L17: =SUM(I17:K17) -> 399 | M17: =$I53 -> 381 | N17: =$I56 -> 0 | O17: =$I59 -> 0 | P17: =SUM(M17:O17) -> 381 | Q17: =H17+L17-P17 -> 159 | R17: =M17+S17 -> 381 | S17: 0 | T17: 0
A18: 5 | B18: Масло моторное М-8В | F18: л | G18: - | H18: 0 | I18: =$J41 -> 13.5 | J18: =$J48 -> 0 | K18: =$J51 -> 0 | L18: =SUM(I18:K18) -> 13.5 | M18: =$J53 -> 7.5 | N18: =$J56 -> 0 | O18: =$J59 -> 0 | P18: =SUM(M18:O18) -> 7.5 | Q18: =H18+L18-P18 -> 6 | R18: =M18+S18 -> 7.5 | S18: 0 | T18: 0
A19: 6 | B19: Масло моторное 5W-30 SN/CF | F19: л | G19: - | H19: 0 | I19: =$L41 -> 8 | J19: =$L48 -> 0 | K19: =$L51 -> 0 | L19: =SUM(I19:K19) -> 8 | M19: =$L53 -> 0 | N19: =$L56 -> 0 | O19: =$L59 -> 8 | P19: =SUM(M19:O19) -> 8 | Q19: =H19+L19-P19 -> 0 | R19: =M19+S19 -> 0 | S19: 0 | T19: 0
A20: 7 | B20: Масло трансмис. ТЭП-15 | F20: л | G20: - | H20: 0 | I20: =$Q41 -> 0 | J20: =$Q48 -> 0 | K20: =$Q51 -> 0 | L20: =SUM(I20:K20) -> 0 | M20: =$Q53 -> 0 | N20: =$Q56 -> 0 | O20: =$Q59 -> 0 | P20: =SUM(M20:O20) -> 0 | Q20: =H20+L20-P20 -> 0 | R20: =M20+S20 -> 0 | S20: 0 | T20: 0
A21: 8 | B21: Масло марки «Р» | F21: л | G21: - | H21: 0 | I21: =$S41 -> 0 | J21: =$S48 -> 0 | K21: =$S51 -> 0 | L21: =SUM(I21:K21) -> 0 | M21: =$S53 -> 0 | N21: =$S56 -> 0 | O21: =$S59 -> 0 | P21: =SUM(M21:O21) -> 0 | Q21: =H21+L21-P21 -> 0 | R21: =M21+S21 -> 0 | S21: 0 | T21: 0
A22: 9 | B22: Масло моторное 5W-40 SN/CF (синт.) | F22: л | G22: - | H22: 0 | I22: =$N41 -> 11.6 | J22: =$N48 -> 0 | K22: =$N51 -> 0 | L22: =SUM(I22:K22) -> 11.6 | M22: =$N53 -> 0 | N22: =$N56 -> 0 | O22: =$N59 -> 11.6 | P22: =SUM(M22:O22) -> 11.6 | Q22: =H22+L22-P22 -> 0 | R22: =M22+S22+O22 -> 11.6 | S22: 0 | T22: 0
A23: 10 | B23: Масло моторное 5W-40 SL/CF (полусинт.) | F23: л | G23: - | H23: 0 | I23: =$M41 -> 4.4 | J23: =$M48 -> 0 | K23: =$M51 -> 0 | L23: =SUM(I23:K23) -> 4.4 | M23: =$M53 -> 4.4 | N23: =$M56 -> 0 | O23: =$M59 -> 0 | P23: =SUM(M23:O23) -> 4.4 | Q23: =H23+L23-P23 -> 0 | R23: =M23+S23+O23 -> 4.4 | S23: 0 | T23: 0
A24: 11 | B24: Масло моторное 10W-40 SL/CF | F24: л | G24: - | H24: 6 | I24: =$O41 -> 28 | J24: =$O48 -> 0 | K24: =$O51 -> 0 | L24: =SUM(I24:K24) -> 28 | M24: =$O53 -> 11 | N24: =$O56 -> 0 | O24: =$O59 -> 23 | P24: =SUM(M24:O24) -> 34 | Q24: =H24+L24-P24 -> 0 | R24: =M24+S24+O24 -> 34 | S24: 0 | T24: 0
A25: 12 | B25: Масло моторное 10W-40 СI-4/CL | F25: л | G25: - | H25: 0 | I25: =$P41 -> 0 | J25: =$P48 -> 0 | K25: =$P51 -> 0 | L25: =SUM(I25:K25) -> 0 | M25: =$P53 -> 0 | N25: =$P56 -> 0 | O25: =$P59 -> 0 | P25: =SUM(M25:O25) -> 0 | Q25: =H25+L25-P25 -> 0 | R25: =M25+S25 -> 0 | S25: 0 | T25: 0
A26: 13 | B26: Масло трансм. 75W-90 API GL-5 | F26: л | G26: - | H26: 0 | I26: =$R41 -> 0 | J26: =$R48 -> 0 | K26: =$R51 -> 0 | L26: =SUM(I26:K26) -> 0 | M26: =$R53 -> 0 | N26: =$R56 -> 0 | O26: =$R59 -> 0 | P26: =SUM(M26:O26) -> 0 | Q26: =H26+L26-P26 -> 0 | R26: =M26+S26 -> 0 | S26: 0 | T26: 0
A27: 14 | B27: Т/Ж «Dot-4» | F27: л | G27: - | H27: 0 | I27: 0 | J27: 0 | K27: 0 | L27: =SUM(I27:K27) -> 0 | M27: 0 | N27: 0 | O27: 0 | P27: =SUM(M27:O27) -> 0 | Q27: =H27+L27-P27 -> 0 | R27: =M27+S27 -> 0 | S27: 0 | T27: 0
A28: 15 | B28: Тосол-А40 | F28: л | G28: - | H28: 475.2 | I28: 0 | J28: 0 | K28: 0 | L28: =SUM(I28:K28) -> 0 | M28: 7.9 | N28: 0 | O28: 0 | P28: =SUM(M28:O28) -> 7.9 | Q28: =H28+L28-P28 -> 467.3 | R28: =M28+S28 -> 7.9 | S28: 0 | T28: 0
A29: 16 | B29: Антифриз зелен. | F29: л | G29: - | H29: 127.8 | I29: 0 | J29: 0 | K29: 0 | L29: =SUM(I29:K29) -> 0 | M29: 3.1 | N29: 0 | O29: 0 | P29: =SUM(M29:O29) -> 3.1 | Q29: =H29+L29-P29 -> 124.7 | R29: =M29+S29 -> 3.1 | S29: 0 | T29: 0
A30: 17 | B30: Антифриз красн. | F30: л | G30: - | H30: 61 | I30: 0 | J30: 0 | K30: 0 | L30: =SUM(I30:K30) -> 0 | M30: 1.5 | N30: 0 | O30: 0 | P30: =SUM(M30:O30) -> 1.5 | Q30: =H30+L30-P30 -> 59.5 | R30: =M30+S30 -> 1.5 | S30: 0 | T30: 0
A31: 18 | B31: Реагент AdBlue | F31: л | G31: - | H31: 6.5 | I31: 10 | J31: 0 | K31: 0 | L31: =SUM(I31:K31) -> 10 | M31: 5.6 | N31: 0 | O31: 0 | P31: =SUM(M31:O31) -> 5.6 | Q31: =H31+L31-P31 -> 10.9 | R31: =M31+S31 -> 5.6 | S31: 0 | T31: 0
A32: 19 | B32: Топливная карта | F32: шт. | G32: - | H32: 1 | I32: 0 | J32: 0 | K32: 0 | L32: =SUM(I32:K32) -> 0 | M32: 0 | N32: 0 | O32: 0 | P32: =SUM(M32:O32) -> 0 | Q32: 1 | R32: =M32+S32 -> 0 | S32: 0 | T32: 0
A33: Итого наименований:18 (восемнадцать)
A34: Наименование графы | B34: Откуда прибыло, куда убыло | D34: Наименование документа | E34: №, дата документа | G34: Наименование и количество ГСМ, ТС
G35: АИ-92 | H35: ДТ-З | I35: АИ-95 | J35: М-8В | K35: М-10Г2/М-10Г2к | L35: 5W-30 SN/CF | M35: 5W-40 SL/CF | N35: 5W-40 SN/CF син. | O35: 10W-40 SL/CF | P35: 10W-40 CI-4/CL | Q35: ТЭП-15 | R35: 75W-90 GL-5 | S35: Масло марки «Р» | T35: AdBlue
A36: 6 | B36: Склад в/ч | D36: Р/в | E36: № 557, 557/1/2/3/4/5 | G36: 4160 | H36: 4001 | I36: 399 | J36: 7.5 | K36: 0 | L36: 0 | M36: 4.4 | N36: 0 | O36: 11 | P36: 0 | Q36: 0 | R36: 0 | S36: 0 | T36: 0
B37: Склад в/ч | D37: Накладная | E37: № 44 от 09.01.2026 | G37: 0 | H37: 0 | I37: 0 | J37: 6 | K37: 0 | L37: 0 | M37: 0 | N37: 0 | O37: 0 | P37: 0 | Q37: 0 | R37: 0 | S37: 0 | T37: 0
D38: Накладная | E38: № 65 от 16.01.2026 | G38: 0 | H38: 0 | I38: 0 | J38: 0 | K38: 0 | L38: 0 | M38: 0 | N38: 11.6 | O38: 0 | P38: 0 | Q38: 0 | R38: 0 | S38: 0 | T38: 0
D39: Накладная | E39: № 1200 от 09.12.2025 | G39: 0 | H39: 0 | I39: 0 | J39: 0 | K39: 0 | L39: 0 | M39: 0 | N39: 0 | O39: 6 | P39: 0 | Q39: 0 | R39: 0 | S39: 0 | T39: 0
B40: Склад в/ч | D40: Накладная | E40: № 30 от 30.12.2025 | G40: 0 | H40: 0 | I40: 0 | J40: 0 | K40: 0 | L40: 8 | M40: 0 | N40: 0 | O40: 11 | P40: 0 | Q40: 0 | R40: 0 | S40: 0 | T40: 0
...

Sheet март
A1: ДОНЕСЕНИЕ №
A2: о наличии и движении ГСМ и ТС 1 гр. ЦМТО войсковой части 2187 по состоянию на | J2: 46101
A3: № п/п | B3: Наименование материальных средств | F3: Единица измерения | G3: Категория | H3: Остаток на начало отчетного периода | I3: Прибыло | M3: Убыло | Q3: Остаток на конец отчетного периода | R3: Положено израсходовать по норме | S3: Экономия | T3: Перерасход
I4: со склада воинской части | J4: из других воинских частей (подразделений) | K4: прочий приход | L4: Всего | M4: фактически сожжено в двигателях, израсходовано на эксплуатационные нужды | N4: передано другим воинским частям (подразделениям) | O4: прочий расход | P4: всего
A5: 1 | B5: 2 | F5: 3 | G5: 4 | H5: 5 | I5: 6 | J5: 7 | K5: 8 | L5: 9 | M5: 10 | N5: 11 | O5: 12 | P5: 13 | Q5: 14 | R5: 15 | S5: 16 | T5: 17
A6: 1 | B6: Автомобильный бензин АИ-92-К5 | F6: л | G6: - | H6: 1555 | I6: =$G42 -> 4250 | J6: =$G50 -> 316 | K6: =$G53 -> 0 | L6: =SUM(I6:K6) -> 4566 | M6: =$G55 -> 4095 | N6: =$G58 -> 147 | O6: =$G61 -> 0 | P6: =SUM(M6:O6) -> 4242 | Q6: =H6+L6-P6 -> 1879 | R6: =M6+S6 -> 4095 | S6: 0 | T6: 0
B7: сентябрь | G7: - | H7: =февраль!Q7 -> -344 | L7: =SUM(I7:K7) -> 0 | M7: =R7-S7 -> 0 | N7: 14 | O7: 158 | P7: =SUM(M7:O7) -> 172 | Q7: =H7+L7-P7 -> -516 | R7: =M7+S7 -> 0 | S7: 0 | T7: 0
B8: октябрь | G8: - | H8: =февраль!Q8 -> 0 | L8: =SUM(I8:K8) -> 0 | M8: =R8-S8 -> 0 | P8: =SUM(M8:O8) -> 0 | Q8: =H8+L8-P8 -> 1389 | R8: =M8+S8 -> 0 | S8: 0 | T8: 0
B9: ноябрь | G9: - | H9: =февраль!Q9 -> 0 | L9: =SUM(I9:K9) -> 0 | M9: =R9-S9 -> 0 | P9: =SUM(M9:O9) -> 0 | Q9: =H9+L9-P9 -> 0 | R9: =M9+S9 -> 0 | S9: 0 | T9: 0
B10: декабрь | G10: - | H10: =февраль!Q10 -> 0 | L10: =SUM(I10:K10) -> 0 | M10: =R10-S10 -> 0 | P10: =SUM(M10:O10) -> 0 | Q10: =H10+L10-P10 -> 1389 | R10: =M10+S10 -> 0 | S10: 0 | T10: 0
B11: январь | G11: - | H11: =февраль!Q11 -> 8068 | I11: 3763 | J11: 271 | L11: =SUM(I11:K11) -> 4034 | M11: =R11-S11 -> 0 | P11: =SUM(M11:O11) -> 0 | Q11: =H11+L11-P11 -> 5423 | R11: =M11+S11 -> 0 | S11: 0 | T11: 0
G12: - | H12: =февраль!Q12 -> 0 | L12: =SUM(I12:K12) -> 0 | M12: =R12-S12 -> 0 | P12: =SUM(M12:O12) -> 0 | Q12: =H12+L12-P12 -> 1389 | R12: =M12+S12 -> 0 | S12: 0 | T12: 0
G13: - | H13: =февраль!Q13 -> 0 | L13: =SUM(I13:K13) -> 0 | M13: =R13-S13 -> 0 | P13: =SUM(M13:O13) -> 0 | Q13: =H13+L13-P13 -> 1389 | R13: =M13+S13 -> 0 | S13: 0 | T13: 0
G14: - | H14: =февраль!Q14 -> 0 | L14: =SUM(I14:K14) -> 0 | M14: =R14-S14 -> 0 | P14: =SUM(M14:O14) -> 0 | Q14: =H14+L14-P14 -> 0 | R14: =M14+S14 -> 0 | S14: 0 | T14: 0
A15: 2 | B15: Дизельное топливо ДТ-Л-К5 | F15: л | G15: - | H15: =февраль!Q15 -> 0 | I15: 0 | J15: 0 | K15: 0 | L15: =SUM(I15:K15) -> 0 | M15: 0 | N15: 0 | O15: 0 | P15: =SUM(M15:O15) -> 0 | Q15: =H15+L15-P15 -> 0 | R15: =M15+S15 -> 0 | S15: 0 | T15: 0
A16: 3 | B16: Дизельное топливо ДТ-З-К5 | F16: л | G16: - | H16: =февраль!Q16 -> 2146 | I16: =$H42 -> 3405 | J16: =$H50 -> 235 | K16: =$H53 -> 0 | L16: =SUM(I16:K16) -> 3640 | M16: =$H55 -> 3778 | N16: =$H58 -> 0 | O16: =$H61 -> 0 | P16: =SUM(M16:O16) -> 3778 | Q16: =H16+L16-P16 -> 2008 | R16: =M16+S16 -> 3778 | S16: 0 | T16: 0
A17: 4 | B17: Автомобильный бензин АИ-95-К5 | F17: л | G17: - | H17: 125 | I17: =$I42 -> 458 | J17: =$I50 -> 0 | K17: =$I53 -> 55 | L17: =SUM(I17:K17) -> 513 | M17: =$I55 -> 536 | N17: =$I58 -> 0 | O17: =$I61 -> 0 | P17: =SUM(M17:O17) -> 536 | Q17: =H17+L17-P17 -> 102 | R17: =M17+S17 -> 536 | S17: 0 | T17: 0
A18: 5 | B18: Масло моторное М-8В | F18: л | G18: - | H18: =февраль!Q18 -> 0 | I18: =$J42 -> 22.5 | J18: =$J50 -> 0 | K18: =$J53 -> 0 | L18: =SUM(I18:K18) -> 22.5 | M18: =$J55 -> 22.5 | N18: =$J58 -> 0 | O18: =$J61 -> 0 | P18: =SUM(M18:O18) -> 22.5 | Q18: =H18+L18-P18 -> 0 | R18: =M18+S18 -> 22.5 | S18: 0 | T18: 0
A19: 6 | B19: Масло моторное 5W-30 SN/CF | F19: л | G19: - | H19: =февраль!Q19 -> 0 | I19: =$L42 -> 8 | J19: =$L50 -> 0 | K19: =$L53 -> 0 | L19: =SUM(I19:K19) -> 8 | M19: =$L55 -> 0.4 | N19: =$L58 -> 0 | O19: =$L61 -> 7.6 | P19: =SUM(M19:O19) -> 8 | Q19: =H19+L19-P19 -> 0 | R19: =M19+S19 -> 0.4 | S19: 0 | T19: 0
A20: 7 | B20: 5W-40 полусинт. | F20: л | G20: - | H20: =февраль!Q20 -> 0 | I20: =$Q42 -> 6 | J20: =$Q50 -> 0 | K20: =$Q53 -> 0 | L20: =SUM(I20:K20) -> 6 | M20: =$Q55 -> 6 | N20: =$Q58 -> 0 | O20: =$Q61 -> 0 | P20: =SUM(M20:O20) -> 6 | Q20: =H20+L20-P20 -> 0 | R20: =M20+S20 -> 6 | S20: 0 | T20: 0
A21: 8 | B21: Масло марки «Р» | F21: л | G21: - | H21: =февраль!Q21 -> 0 | I21: =$S42 -> 1.25 | J21: =$S50 -> 0 | K21: =$S53 -> 0 | L21: =SUM(I21:K21) -> 1.25 | M21: =$S55 -> 1.25 | N21: =$S58 -> 0 | O21: =$S61 -> 0 | P21: =SUM(M21:O21) -> 1.25 | Q21: =H21+L21-P21 -> 0 | R21: =M21+S21 -> 1.25 | S21: 0 | T21: 0
A22: 9 | B22: Масло моторное 5W-40 SN/CF (синт.) | F22: л | G22: - | H22: =февраль!Q22 -> 0 | I22: =$N42 -> 0 | J22: =$N50 -> 0 | K22: =$N53 -> 0 | L22: =SUM(I22:K22) -> 0 | M22: =$N55 -> 0 | N22: =$N58 -> 0 | O22: =$N61 -> 0 | P22: =SUM(M22:O22) -> 0 | Q22: =H22+L22-P22 -> 0 | R22: =M22+S22+O22 -> 0 | S22: 0 | T22: 0
A23: 10 | B23: Масло моторное 5W-40 SL/CF (полусинт.) | F23: л | G23: - | H23: =февраль!Q23 -> 0 | I23: =$M42 -> 9 | J23: =$M50 -> 0 | K23: =$M53 -> 0 | L23: =SUM(I23:K23) -> 9 | M23: =$M55 -> 9 | N23: =$M58 -> 0 | O23: =$M61 -> 0 | P23: =SUM(M23:O23) -> 9 | Q23: =H23+L23-P23 -> 0 | R23: =M23+S23+O23 -> 9 | S23: 0 | T23: 0
A24: 11 | B24: Масло моторное 10W-40 SL/CF | F24: л | G24: - | H24: =февраль!Q24 -> 0 | I24: =$O42 -> 0.5 | J24: =$O50 -> 0 | K24: =$O53 -> 0 | L24: =SUM(I24:K24) -> 0.5 | M24: =$O55 -> 0.5 | N24: =$O58 -> 0 | O24: =$O61 -> 0 | P24: =SUM(M24:O24) -> 0.5 | Q24: =H24+L24-P24 -> 0 | R24: =M24+S24+O24 -> 0.5 | S24: 0 | T24: 0
A25: 12 | B25: Масло моторное 10W-40 СI-4/CL | F25: л | G25: - | H25: =февраль!Q25 -> 0 | I25: =$P42 -> 21 | J25: =$P50 -> 0 | K25: =$P53 -> 0 | L25: =SUM(I25:K25) -> 21 | M25: =$P55 -> 8 | N25: =$P58 -> 0 | O25: =$P61 -> 13 | P25: =SUM(M25:O25) -> 21 | Q25: =H25+L25-P25 -> 0 | R25: =M25+S25 -> 8 | S25: 0 | T25: 0
A26: 13 | B26: Масло трансм. 75W-90 API GL-5 | F26: л | G26: - | H26: =февраль!Q26 -> 0 | I26: =$R42 -> 0.9 | J26: =$R50 -> 0 | K26: =$R53 -> 0 | L26: =SUM(I26:K26) -> 0.9 | M26: =$R55 -> 0.9 | N26: =$R58 -> 0 | O26: =$R61 -> 0 | P26: =SUM(M26:O26) -> 0.9 | Q26: =H26+L26-P26 -> 0 | R26: =M26+S26 -> 0.9 | S26: 0 | T26: 0
A27: 14 | B27: Масло моторное М-10Г2/М-10Г2к | F27: л | G27: - | H27: 0 | I27: =$K42 -> 3 | J27: =$K50 -> 0 | K27: =$K53 -> 0 | L27: =SUM(I27:K27) -> 3 | M27: =$K55 -> 3 | N27: =$K58 -> 0 | O27: =$K61 -> 0 | P27: =SUM(M27:O27) -> 3 | Q27: =H27+L27-P27 -> 0 | R27: =M27+S27 -> 3 | S27: 0 | T27: 0
A28: 15 | B28: Т/Ж «Dot-4» | F28: л | G28: - | H28: =февраль!Q27 -> 0 | I28: 0 | J28: 0 | K28: 0 | L28: =SUM(I28:K28) -> 0 | M28: 0 | N28: 0 | O28: 0 | P28: =SUM(M28:O28) -> 0 | Q28: =H28+L28-P28 -> 0 | R28: =M28+S28 -> 0 | S28: 0 | T28: 0
A29: 16 | B29: Тосол-А40 | F29: л | G29: - | H29: =февраль!Q28 -> 459.1 | I29: 0 | J29: 0 | K29: 0 | L29: =SUM(I29:K29) -> 0 | M29: 13.1 | N29: 0 | O29: 0 | P29: =SUM(M29:O29) -> 13.1 | Q29: =H29+L29-P29 -> 446 | R29: =M29+S29 -> 13.1 | S29: 0 | T29: 0
A30: 17 | B30: Антифриз зелен. | F30: л | G30: - | H30: =февраль!Q29 -> 122.4 | I30: 0 | J30: 0 | K30: 0 | L30: =SUM(I30:K30) -> 0 | M30: 2.6 | N30: 0 | O30: 0 | P30: =SUM(M30:O30) -> 2.6 | Q30: =H30+L30-P30 -> 119.8 | R30: =M30+S30 -> 2.6 | S30: 0 | T30: 0
A31: 18 | B31: Антифриз красн. | F31: л | G31: - | H31: =февраль!Q30 -> 58 | I31: 0 | J31: 0 | K31: 0 | L31: =SUM(I31:K31) -> 0 | M31: 1.4 | N31: 0 | O31: 0 | P31: =SUM(M31:O31) -> 1.4 | Q31: =H31+L31-P31 -> 56.6 | R31: =M31+S31 -> 1.4 | S31: 0 | T31: 0
A32: 19 | B32: Реагент AdBlue | F32: л | G32: - | H32: =февраль!Q31 -> 7.1 | I32: 20 | J32: 0 | K32: 0 | L32: =SUM(I32:K32) -> 20 | M32: 20.8 | N32: 0 | O32: 0 | P32: =SUM(M32:O32) -> 20.8 | Q32: =H32+L32-P32 -> 6.3 | R32: =M32+S32 -> 20.8 | S32: 0 | T32: 0
A33: 20 | B33: Топливная карта | F33: шт. | G33: - | H33: =февраль!Q32 -> 1 | I33: 0 | J33: 0 | K33: 0 | L33: =SUM(I33:K33) -> 0 | M33: 0 | N33: 0 | O33: 0 | P33: =SUM(M33:O33) -> 0 | Q33: 1 | R33: =M33+S33 -> 0 | S33: 0 | T33: 0
A34: Итого наименований: 20 (Двадцать)
A35: Наименование графы | B35: Откуда прибыло, куда убыло | D35: Наименование документа | E35: №, дата документа | G35: Наименование и количество ГСМ, ТС
G36: АИ-92 | H36: ДТ-З | I36: АИ-95 | J36: М-8В | K36: М-10Г2/М-10Г2к | L36: 5W-30 SN/CF | M36: 5W-40 SL/CF | N36: 5W-40 SN/CF син. | O36: 10W-40 SL/CF | P36: 10W-40 CI-4/CL | Q36: 5W-40 полусинт. | R36: 75W-90 GL-5 | S36: Масло марки «Р» | T36: AdBlue
A37: 6 | B37: Склад в/ч | D37: Р/в | E37: № 126, 126/1/2/3/4/5 | G37: 4250 | H37: 3405 | I37: 458 | J37: 22.5 | K37: 3 | L37: 0.4 | M37: 9 | N37: 0 | O37: 0.5 | P37: 8 | Q37: 6 | R37: 0.9 | S37: 1.25 | T37: 20
B38: Склад в/ч | D38: Накладная | E38: 207 | G38: 0 | H38: 0 | I38: 0 | J38: 0 | K38: 0 | L38: 0 | M38: 0 | N38: 0 | O38: 0 | P38: 6.5 | Q38: 0 | R38: 0 | S38: 0 | T38: 0
D39: Накладная | E39: 233 | G39: 0 | H39: 0 | I39: 0 | J39: 0 | K39: 0 | L39: 7.6 | M39: 0 | N39: 0 | O39: 0 | P39: 0 | Q39: 0 | R39: 0 | S39: 0 | T39: 0
D40: Накладная | E40: 249 | G40: 0 | H40: 0 | I40: 0 | J40: 0 | K40: 0 | L40: 0 | M40: 0 | N40: 0 | O40: 0 | P40: 6.5 | Q40: 0 | R40: 0 | S40: 0 | T40: 0
...

Sheet апрель

Sheet май

Sheet июнь

Sheet июль

Sheet август

Sheet сентябрь

Sheet октябрь

Sheet ноябрь

Sheet декабрь
